<?xml version="1.0" encoding="utf-8"?>
<!-- This URDF was automatically created by SolidWorks to URDF Exporter! Originally created by Stephen Brawner (brawner@gmail.com) 
     Commit Version: 1.6.0-4-g7f85cfe  Build Version: 1.6.7995.38578
     For more information, please see http://wiki.ros.org/sw_urdf_exporter -->
<robot
  name="FourWheelRobot10">
  <link
    name="base_link">
    <inertial>
      <origin
        xyz="0.00026004 4.1672E-09 0.018516"
        rpy="0 0 0" />
      <mass
        value="2.5" />
      <inertia
        ixx="3.2767E-05"
        ixy="-1.3847E-13"
        ixz="1.4164E-21"
        iyy="8.0608E-05"
        iyz="-4.7145E-24"
        izz="0.00010799" />
    </inertial>
    <visual>
      <origin
        xyz="0 0 0"
        rpy="0 0 0" />
      <geometry>
        <mesh
          filename="package://FourWheelRobot10/meshes/base_link.STL" />
      </geometry>
      <material
        name="">
        <color
          rgba="0.2 0.2 0.2 1" />
      </material>
    </visual>
    <collision>
      <origin
        xyz="0 0 0"
        rpy="0 0 0" />
      <geometry>
        <mesh
          filename="package://FourWheelRobot10/meshes/base_link.STL" />
      </geometry>
    </collision>
  </link>
  <link
    name="link_1">
    <inertial>
      <origin
        xyz="8.1037E-06 -1.9918E-06 -0.0077661"
        rpy="0 0 0" />
      <mass
        value="0.5" />
      <inertia
        ixx="5.9082E-06"
        ixy="2.7993E-10"
        ixz="1.0863E-10"
        iyy="5.9095E-06"
        iyz="-7.3757E-12"
        izz="8.9148E-06" />
    </inertial>
    <visual>
      <origin
        xyz="0 0 0"
        rpy="0 0 0" />
      <geometry>
        <mesh
          filename="package://FourWheelRobot10/meshes/link_1.STL" />
      </geometry>
      <material
        name="">
        <color
          rgba="0.29804 0.29804 0.29804 1" />
      </material>
    </visual>
    <collision>
      <origin
        xyz="0 0 0"
        rpy="0 0 0" />
      <geometry>
        <mesh
          filename="package://FourWheelRobot10/meshes/link_1.STL" />
      </geometry>
    </collision>
  </link>
  <joint
    name="joint_1"
    type="continuous">
    <origin
      xyz="-0.0506999999999997 -0.0538199958328328 0.0186"
      rpy="1.5707963267949 0 3.14159265358979" />
    <parent
      link="base_link" />
    <child
      link="link_1" />
    <axis
      xyz="0 0 1" />
  </joint>
  <link
    name="link_2">
    <inertial>
      <origin
        xyz="3.5739E-06 -8.7338E-06 -0.0077661"
        rpy="0 0 0" />
      <mass
        value="0.5" />
      <inertia
        ixx="5.9094E-06"
        ixy="4.0736E-10"
        ixz="-2.8613E-11"
        iyy="5.9083E-06"
        iyz="-5.3573E-11"
        izz="8.9148E-06" />
    </inertial>
    <visual>
      <origin
        xyz="0 0 0"
        rpy="0 0 0" />
      <geometry>
        <mesh
          filename="package://FourWheelRobot10/meshes/link_2.STL" />
      </geometry>
      <material
        name="">
        <color
          rgba="0.29804 0.29804 0.29804 1" />
      </material>
    </visual>
    <collision>
      <origin
        xyz="0 0 0"
        rpy="0 0 0" />
      <geometry>
        <mesh
          filename="package://FourWheelRobot10/meshes/link_2.STL" />
      </geometry>
    </collision>
  </link>
  <joint
    name="joint_2"
    type="continuous">
    <origin
      xyz="0.0507000000000003 -0.0538199958328328 0.0186"
      rpy="1.5707963267949 0 3.14159265358979" />
    <parent
      link="base_link" />
    <child
      link="link_2" />
    <axis
      xyz="0 0 1" />
  </joint>
  <link
    name="link_3">
    <inertial>
      <origin
        xyz="-8.1037E-06 -1.9918E-06 0.0077661"
        rpy="0 0 0" />
      <mass
        value="0.5" />
      <inertia
        ixx="5.9082E-06"
        ixy="-2.7993E-10"
        ixz="1.0863E-10"
        iyy="5.9095E-06"
        iyz="7.3757E-12"
        izz="8.9148E-06" />
    </inertial>
    <visual>
      <origin
        xyz="0 0 0"
        rpy="0 0 0" />
      <geometry>
        <mesh
          filename="package://FourWheelRobot10/meshes/link_3.STL" />
      </geometry>
      <material
        name="">
        <color
          rgba="0.29804 0.29804 0.29804 1" />
      </material>
    </visual>
    <collision>
      <origin
        xyz="0 0 0"
        rpy="0 0 0" />
      <geometry>
        <mesh
          filename="package://FourWheelRobot10/meshes/link_3.STL" />
      </geometry>
    </collision>
  </link>
  <joint
    name="joint_3"
    type="continuous">
    <origin
      xyz="0.0507000000000003 0.0538200041671672 0.0186"
      rpy="1.5707963267949 0 3.14159265358979" />
    <parent
      link="base_link" />
    <child
      link="link_3" />
    <axis
      xyz="0 0 -1" />
  </joint>
  <link
    name="link_4">
    <inertial>
      <origin
        xyz="1.9112E-06 8.7338E-06 0.00056606"
        rpy="0 0 0" />
      <mass
        value="0.5" />
      <inertia
        ixx="5.9094E-06"
        ixy="-4.0736E-10"
        ixz="-7.3441E-11"
        iyy="5.9083E-06"
        iyz="-5.3573E-11"
        izz="8.9148E-06" />
    </inertial>
    <visual>
      <origin
        xyz="0 0 0"
        rpy="0 0 0" />
      <geometry>
        <mesh
          filename="package://FourWheelRobot10/meshes/link_4.STL" />
      </geometry>
      <material
        name="">
        <color
          rgba="0.29804 0.29804 0.29804 1" />
      </material>
    </visual>
    <collision>
      <origin
        xyz="0 0 0"
        rpy="0 0 0" />
      <geometry>
        <mesh
          filename="package://FourWheelRobot10/meshes/link_4.STL" />
      </geometry>
    </collision>
  </link>
  <joint
    name="joint_4"
    type="continuous">
    <origin
      xyz="-0.0506999999999997 0.0610200041671672 0.0186"
      rpy="1.5707963267949 0 3.14159265358979" />
    <parent
      link="base_link" />
    <child
      link="link_4" />
    <axis
      xyz="0 0 -1" />
  </joint>
</robot>